Workbook

Sheet Summary
B1: Update the newly bought shuttlecocks with its tube name,price and holder name under the "Record" table.
A3: Shuttlecocks Money Summary
B6: =SUM(C15:C1001) -> 4098.972 | D6: =SUM(Records!D4:D1001) -> 460
B7: wasted :( | D7: dead cocks
B10: Cocks Bought | C10: =SUM(E15:E1001) -> 514 | D10: =IFERROR(__xludf.DUMMYFUNCTION("SPARKLINE(C10,{""charttype"",""bar"";""max"",max(C10:C11);""color1"",""#AEB7C0""})"),"") | I10: Upcoming plan: | K10: Brand Pie Chart
B11: Cocks Left | C11: =SUM(F15:F1001) -> 54 | D11: =IFERROR(__xludf.DUMMYFUNCTION("SPARKLINE(C11,{""charttype"",""bar"";""max"",max(C10:C11);""color1"",""#334960""})"),"")
B13: Record | J13: Payment
B14: Tubes | C14: Price | D14: Per Ball | E14: Ball | F14: Ball left | G14: Holder | H14: Status | J14: Tube | K14: RSL S19
A15: 1 | B15: Pomax | C15: 77.9 | D15: =C15/E15 -> 6.4916667 | E15: 12 | F15: =E15-SUMIF(Records!$C:$C,B15,Records!$D:$D) -> 0 | G15: Poi | H15: TRUE | J15: Payment | K15: Amount
A16: 2 | B16: Pomax 2 | C16: 78.41 | D16: =C16/E16 -> 6.5341667 | E16: 12 | F16: =E16-SUMIF(Records!$C:$C,B16,Records!$D:$D) -> 0 | G16: Poi | H16: TRUE | J16: Poi | K16: =SUMIF(Calculations!$C$4:$C1001,$K$14,Calculations!$G$4:$G1001) -> 18.449206
A17: 3 | B17: DimG | C17: 86 | D17: =C17/E17 -> 7.1666667 | E17: 12 | F17: =E17-SUMIF(Records!$C:$C,B17,Records!$D:$D) -> 0 | G17: Poi | H17: TRUE | J17: ZT | K17: =SUMIF(Calculations!$C$4:$C1001,$K$14,Calculations!$H$4:$H1001) -> 5.5347619
A18: 4 | B18: RSL C | C18: 76.67 | D18: =C18/E18 -> 6.3891667 | E18: 12 | F18: =E18-SUMIF(Records!$C:$C,B18,Records!$D:$D) -> 0 | G18: Poi | H18: TRUE | J18: YZ | K18: =SUMIF(Calculations!$C$4:$C1001,$K$14,Calculations!$I$4:$I1001) -> 0
A19: 5 | B19: Sealion | C19: 69.36 | D19: =C19/E19 -> 5.78 | E19: 12 | F19: =E19-SUMIF(Records!$C:$C,B19,Records!$D:$D) -> 0 | G19: Poi | H19: TRUE | J19: KC | K19: =SUMIF(Calculations!$C$4:$C1001,$K$14,Calculations!$J$4:$J1001) -> 8.763373
A20: 6 | B20: AS 50 | C20: 105 | D20: =C20/E20 -> 8.75 | E20: 12 | F20: =E20-SUMIF(Records!$C:$C,B20,Records!$D:$D) -> 0 | G20: Poi | H20: TRUE | J20: CJ | K20: =SUMIF(Calculations!$C$4:$C1001,$K$14,Calculations!$K$4:$K1001) -> 18.449206
A21: 7 | B21: Felet Orange | C21: 75 | D21: =C21/E21 -> 6.25 | E21: 12 | F21: =E21-SUMIF(Records!$C:$C,B21,Records!$D:$D) -> 0 | G21: Poi | H21: TRUE | J21: HX | K21: =SUMIF(Calculations!$C$4:$C1001,$K$14,Calculations!$L$4:$L1001) -> 18.449206
A22: 8 | B22: RSL S | C22: 76.41 | D22: =C22/E22 -> 6.3675 | E22: 12 | F22: =E22-SUMIF(Records!$C:$C,B22,Records!$D:$D) -> 0 | G22: Poi | H22: TRUE | J22: JZ | K22: =SUMIF(Calculations!$C$4:$C1001,$K$14,Calculations!$M$4:$M1001) -> 9.6858333
A23: 9 | B23: RSL S2 | C23: 80 | D23: =C23/E23 -> 6.6666667 | E23: 12 | F23: =E23-SUMIF(Records!$C:$C,B23,Records!$D:$D) -> 0 | G23: Poi | H23: TRUE | J23: LW | K23: =SUMIF(Calculations!$C$4:$C1001,$K$14,Calculations!$N$4:$N1001) -> 0
A24: 10 | B24: Protech Plat | C24: 69.36 | D24: =C24/E24 -> 5.78 | E24: 12 | F24: =E24-SUMIF(Records!$C:$C,B24,Records!$D:$D) -> 0 | G24: Poi | H24: TRUE | J24: KY | K24: =SUMIF(Calculations!$C$4:$C1001,$K$14,Calculations!$O$4:$O1001) -> 18.449206
A25: 11 | B25: RSL S Stream | C25: 75.39 | D25: =C25/E25 -> 6.2825 | E25: 12 | F25: =E25-SUMIF(Records!$C:$C,B25,Records!$D:$D) -> 0 | G25: Poi | H25: TRUE | J25: Jit Loong | K25: =SUMIF(Calculations!$C$4:$C1001,$K$14,Calculations!$P$4:$P1001) -> 0
A26: 12 | B26: RSL Smash | C26: 61.3 | D26: =C26/E26 -> 5.1083333 | E26: 12 | F26: =E26-SUMIF(Records!$C:$C,B26,Records!$D:$D) -> 0 | G26: Poi | H26: TRUE | J26: Matthew | K26: =SUMIF(Calculations!$C$4:$C1001,$K$14,Calculations!$Q$4:$Q1001) -> 0
A27: 13 | B27: Protech Plat 2 | C27: 74.98 | D27: =C27/E27 -> 6.2483333 | E27: 12 | F27: =E27-SUMIF(Records!$C:$C,B27,Records!$D:$D) -> 0 | G27: Poi | H27: TRUE | J27: Hau Jin | K27: =SUMIF(Calculations!$C$4:$C1001,$K$14,Calculations!$R$4:$R1001) -> 0
A28: 14 | B28: Protech Plat 3 | C28: 74.98 | D28: =C28/E28 -> 6.2483333 | E28: 12 | F28: =E28-SUMIF(Records!$C:$C,B28,Records!$D:$D) -> 0 | G28: Poi | H28: TRUE | J28: Kit Liang | K28: =SUMIF(Calculations!$C$4:$C1001,$K$14,Calculations!$S$4:$S1001) -> 0
A29: 15 | B29: RSL S3 | C29: 85.87 | D29: =C29/E29 -> 7.1558333 | E29: 12 | F29: =E29-SUMIF(Records!$C:$C,B29,Records!$D:$D) -> 0 | G29: Poi | H29: TRUE | J29: YL | K29: =SUMIF(Calculations!$C$4:$C1001,$K$14,Calculations!$T$4:$T1001) -> 8.763373
A30: 16 | B30: RSL S4 | C30: 85.87 | D30: =C30/E30 -> 7.1558333 | E30: 12 | F30: =E30-SUMIF(Records!$C:$C,B30,Records!$D:$D) -> 0 | G30: Poi | H30: TRUE | J30: YX | K30: =SUMIF(Calculations!$C$4:$C1001,$K$14,Calculations!$U$4:$U1001) -> 0
A31: 17 | B31: RCL T | C31: 50 | D31: =C31/E31 -> 5 | E31: 10 | F31: =E31-SUMIF(Records!$C:$C,B31,Records!$D:$D) -> 0 | G31: Poi | H31: TRUE | J31: ZZ | K31: =SUMIF(Calculations!$C$4:$C1001,$K$14,Calculations!$V$4:$V1001) -> 9.6858333
A32: 18 | B32: LM Orange | C32: 87.86 | D32: =C32/E32 -> 7.3216667 | E32: 12 | F32: =E32-SUMIF(Records!$C:$C,B32,Records!$D:$D) -> 0 | G32: Poi | H32: TRUE | J32: Total | K32: =SUM(K16:K31) -> 116.23
A33: 19 | B33: LM DG | C33: 87.86 | D33: =C33/E33 -> 7.3216667 | E33: 12 | F33: =E33-SUMIF(Records!$C:$C,B33,Records!$D:$D) -> 0 | G33: Poi | H33: TRUE
A34: 20 | B34: LM Black | C34: 96.86 | D34: =C34/E34 -> 8.0716667 | E34: 12 | F34: =E34-SUMIF(Records!$C:$C,B34,Records!$D:$D) -> 0 | G34: Poi | H34: TRUE
A35: 21 | B35: LM DG2 | C35: 97.59 | D35: =C35/E35 -> 8.1325 | E35: 12 | F35: =E35-SUMIF(Records!$C:$C,B35,Records!$D:$D) -> 0 | G35: Poi | H35: TRUE
A36: 22 | B36: RCL BG | C36: 96.1 | D36: =C36/E36 -> 8.0083333 | E36: 12 | F36: =E36-SUMIF(Records!$C:$C,B36,Records!$D:$D) -> 0 | G36: Poi | H36: TRUE
A37: 23 | B37: RCL BG2 | C37: 96.1 | D37: =C37/E37 -> 8.0083333 | E37: 12 | F37: =E37-SUMIF(Records!$C:$C,B37,Records!$D:$D) -> 0 | G37: Poi | H37: TRUE
A38: 24 | B38: RSL S5 | C38: 98.77 | D38: =C38/E38 -> 8.2308333 | E38: 12 | F38: =E38-SUMIF(Records!$C:$C,B38,Records!$D:$D) -> 0 | G38: Poi | H38: TRUE
A39: 25 | B39: RSL S6 | C39: 98.77 | D39: =C39/E39 -> 8.2308333 | E39: 12 | F39: =E39-SUMIF(Records!$C:$C,B39,Records!$D:$D) -> 0 | G39: Poi | H39: TRUE
A40: 26 | B40: RSL S7 | C40: 101.5 | D40: =C40/E40 -> 8.4583333 | E40: 12 | F40: =E40-SUMIF(Records!$C:$C,B40,Records!$D:$D) -> 0 | G40: Poi | H40: TRUE
A41: 27 | B41: RSL S8 | C41: 101.5 | D41: =C41/E41 -> 8.4583333 | E41: 12 | F41: =E41-SUMIF(Records!$C:$C,B41,Records!$D:$D) -> 0 | G41: Poi | H41: TRUE
A42: 28 | B42: RSL S9 | C42: 101.37 | D42: =C42/E42 -> 8.4475 | E42: 12 | F42: =E42-SUMIF(Records!$C:$C,B42,Records!$D:$D) -> 0 | G42: Poi | H42: TRUE
A43: 29 | B43: RSL S10 | C43: 101.37 | D43: =C43/E43 -> 8.4475 | E43: 12 | F43: =E43-SUMIF(Records!$C:$C,B43,Records!$D:$D) -> 0 | G43: Poi | H43: TRUE
A44: 30 | B44: RSL S11 | C44: 104.87 | D44: =C44/E44 -> 8.7391667 | E44: 12 | F44: =E44-SUMIF(Records!$C:$C,B44,Records!$D:$D) -> 0 | G44: Poi | H44: TRUE
... A57: 43 | B57: RSL S22 | C57: 126.967 | D57: =C57/E57 -> 10.580583 | E57: 12 | F57: =E57-SUMIF(Records!$C:$C,B57,Records!$D:$D) -> 10 | G57: Poi | H57: FALSE
A58: 44 | H58: FALSE
...

Sheet Records
B1: Update the following informations and leave highlighted cells unedited.
B3: Date | C3: Tube | D3: Ball used | E3: User | G3: Poi | H3: ZT | I3: YZ | J3: KC | K3: CJ | L3: HX | M3: JZ | N3: LW | O3: KY | P3: Jit Loong | Q3: Matthew | R3: Hau Jin | S3: Kit Liang | T3: YL | U3: YX | V3: ZZ
B4: 45182 | C4: Pomax | D4: 2 | E4: =SUM(G4:AM4) -> 5 | G4: 1 | J4: 1 | L4: 1 | T4: 1 | V4: 1
B5: 45197 | C5: Pomax | D5: 3 | E5: =SUM(G5:AM5) -> 8 | G5: 1 | I5: 1 | J5: 1 | L5: 1 | O5: 1 | Q5: 1 | U5: 1 | V5: 1
B6: 45200 | C6: Pomax | D6: 4 | E6: =SUM(G6:AM6) -> 11 | G6: 1 | H6: 1 | I6: 1 | J6: 1 | K6: 1 | M6: 1 | N6: 1 | O6: 1 | Q6: 1 | T6: 1 | U6: 1
B7: 45207 | C7: Pomax | D7: 2 | E7: =SUM(G7:AM7) -> 6 | G7: 1 | H7: 1 | I7: 1 | J7: 1 | K7: 1 | O7: 1
B8: 45219 | C8: Pomax | D8: 1 | E8: =SUM(G8:AM8) -> 1 | G8: 1
B9: 45221 | C9: Pomax 2 | D9: 5 | E9: =SUM(G9:AM9) -> 9 | G9: 1 | H9: 1 | J9: 1 | K9: 1 | N9: 1 | O9: 1 | P9: 1 | Q9: 1 | T9: 1
B10: 45228 | C10: Pomax 2 | D10: 4 | E10: =SUM(G10:AM10) -> 9 | G10: 1 | H10: 1 | I10: 1 | J10: 1 | K10: 1 | L10: 1 | O10: 1 | Q10: 1 | T10: 1
B11: 45235 | C11: Pomax 2 | D11: 3 | E11: =SUM(G11:AM11) -> 10 | G11: 1 | H11: 1 | I11: 1 | J11: 1 | K11: 1 | L11: 1 | M11: 1 | O11: 1 | Q11: 1 | T11: 1
B12: 45629 | C12: DimG | D12: 3 | E12: =SUM(G12:AM12) -> 7 | G12: 1 | J12: 1 | K12: 1 | L12: 1 | O12: 1 | Q12: 1 | V12: 1
B13: 45270 | C13: DimG | D13: 3 | E13: =SUM(G13:AM13) -> 6 | G13: 1 | H13: 1 | I13: 1 | J13: 1 | K13: 1 | L13: 1
B14: 45277 | C14: DimG | D14: 3 | E14: =SUM(G14:AM14) -> 6 | G14: 1 | H14: 1 | I14: 1 | J14: 1 | K14: 1 | T14: 1
B15: 45283 | C15: DimG | D15: 3 | E15: =SUM(G15:AM15) -> 7 | G15: 1 | H15: 1 | I15: 1 | J15: 1 | K15: 1 | L15: 1 | T15: 1
B16: 45236 | C16: RSL C | D16: 2 | E16: =SUM(G16:AM16) -> 10 | G16: 1 | H16: 1 | I16: 1 | J16: 1 | K16: 1 | L16: 1 | M16: 1 | O16: 1 | Q16: 1 | T16: 1
B17: 45242 | C17: RSL C | D17: 4 | E17: =SUM(G17:AM17) -> 8 | G17: 1 | H17: 1 | J17: 1 | K17: 1 | L17: 1 | N17: 1 | O17: 1 | T17: 1
B18: 45250 | C18: RSL C | D18: 2 | E18: =SUM(G18:AM18) -> 9 | G18: 1 | H18: 1 | I18: 1 | J18: 1 | K18: 1 | N18: 1 | O18: 1 | Q18: 1 | T18: 1
B19: 45257 | C19: RSL C | D19: 4 | E19: =SUM(G19:AM19) -> 7 | G19: 1 | H19: 1 | I19: 1 | J19: 1 | K19: 1 | O19: 1 | Q19: 1
B20: 45296 | C20: Sealion | D20: 1 | E20: =SUM(G20:AM20) -> 1 | G20: 1
B21: 45298 | C21: Sealion | D21: 4 | E21: =SUM(G21:AM21) -> 7 | G21: 1 | H21: 1 | I21: 1 | J21: 1 | K21: 1 | O21: 1 | T21: 1
B22: 45305 | C22: Sealion | D22: 5 | E22: =SUM(G22:AM22) -> 8 | G22: 1 | H22: 1 | I22: 1 | J22: 1 | K22: 1 | L22: 1 | M22: 1 | O22: 1
B23: 45340 | C23: Sealion | D23: 2 | E23: =SUM(G23:AM23) -> 6 | G23: 1 | I23: 1 | J23: 1 | L23: 1 | R23: 1 | V23: 1
B24: 45221 | C24: AS 50 | D24: 2 | E24: =SUM(G24:AM24) -> 9 | G24: 1 | H24: 1 | I24: 1 | J24: 1 | K24: 1 | N24: 1 | O24: 1 | Q24: 1 | T24: 1
B25: 45291 | C25: AS 50 | D25: 5 | E25: =SUM(G25:AM25) -> 10 | G25: 1 | H25: 1 | I25: 2 | J25: 1 | K25: 1 | L25: 1 | O25: 1 | T25: 1 | V25: 1
B26: 45343 | C26: AS 50 | D26: 2 | E26: =SUM(G26:AM26) -> 10 | G26: 1 | H26: 2 | I26: 1 | J26: 1 | K26: 1 | L26: 1 | M26: 1 | O26: 1 | T26: 1
B27: 45340 | C27: Felet Orange | D27: 2 | E27: =SUM(G27:AM27) -> 6 | G27: 1 | I27: 1 | J27: 1 | L27: 1 | R27: 1 | V27: 1
B28: 45343 | C28: Felet Orange | D28: 1 | E28: =SUM(G28:AM28) -> 10 | G28: 1 | H28: 2 | I28: 1 | J28: 1 | K28: 1 | L28: 1 | M28: 1 | O28: 1 | T28: 1
B29: 45319 | C29: Felet Orange | D29: 5 | E29: =SUM(G29:AM29) -> 7 | G29: 1 | H29: 1 | J29: 1 | K29: 1 | L29: 1 | O29: 1 | T29: 1
B30: 45326 | C30: Felet Orange | D30: 2 | E30: =SUM(G30:AM30) -> 8 | G30: 1 | H30: 1 | I30: 1 | J30: 1 | L30: 1 | O30: 1 | R30: 1 | T30: 1
B31: 45326 | C31: AS 50 | D31: 2 | E31: =SUM(G31:AM31) -> 8 | G31: 1 | H31: 1 | I31: 1 | J31: 1 | L31: 1 | O31: 1 | R31: 1 | T31: 1
B32: 45330 | C32: AS 50 | D32: 1 | E32: =SUM(G32:AM32) -> 8 | G32: 1 | H32: 1 | I32: 1 | J32: 1 | L32: 1 | M32: 1 | R32: 1 | U32: 1
B33: 45330 | C33: Felet Orange | D33: 2 | E33: =SUM(G33:AM33) -> 8 | G33: 1 | H33: 1 | I33: 1 | J33: 1 | L33: 1 | M33: 1 | R33: 1 | U33: 1
B34: 45330 | C34: RSL S | D34: 3 | E34: =SUM(G34:AM34) -> 8 | G34: 1 | H34: 1 | I34: 1 | J34: 1 | L34: 1 | M34: 1 | R34: 1 | U34: 1
B35: 45347 | C35: RSL S | D35: 5 | E35: =SUM(G35:AM35) -> 7 | G35: 1 | I35: 1 | J35: 1 | K35: 1 | O35: 1 | R35: 1 | S35: 1
B36: 45361 | C36: RSL S | D36: 4 | E36: =SUM(G36:AM36) -> 8 | G36: 1 | H36: 1 | J36: 1 | K36: 1 | L36: 1 | O36: 1 | R36: 1 | T36: 1
B37: 45368 | C37: Protech Plat | D37: 7 | E37: =SUM(G37:AM37) -> 8 | G37: 1 | H37: 1 | I37: 1 | J37: 1 | K37: 1 | L37: 1 | O37: 1 | T37: 1
B38: 45371 | C38: Protech Plat | D38: 3 | E38: =SUM(G38:AM38) -> 1 | G38: 1
B39: 45374 | C39: Protech Plat | D39: 2 | E39: =SUM(G39:AM39) -> 8 | G39: 1 | H39: 1 | I39: 1 | J39: 1 | K39: 1 | L39: 1 | O39: 1 | T39: 1
B40: 45382 | C40: RSL S2 | D40: 4 | E40: =SUM(G40:AM40) -> 7 | G40: 1 | H40: 1 | J40: 1 | K40: 1 | L40: 1 | O40: 1 | T40: 1
B41: 45385 | C41: RSL Smash | D41: 1 | E41: =SUM(G41:AM41) -> 1 | G41: 1
...

Sheet Calculations
B3: Date | C3: Tube | D3: Ball price | E3: Weightage | G3: Poi | H3: ZT | I3: YZ | J3: KC | K3: CJ | L3: HX | M3: JZ | N3: LW | O3: KY | P3: Jit Loong | Q3: Matthew | R3: Hau Jin | S3: Kit Liang | T3: YL | U3: YX | V3: ZZ
B4: =Records!B4 -> 45182 | C4: =Records!$C4 -> Pomax | D4: =SUMIF(Summary!$B$15:$B$31,C4,Summary!$D$15:$D$31) -> 6.4916667 | E4: =if(Records!E4=0,0,D4*Records!D4/Records!E4) -> 2.5966667 | G4: =Records!G4*$E4 -> 2.5966667 | H4: =Records!H4*$E4 -> 0 | I4: =Records!I4*$E4 -> 0 | J4: =Records!J4*$E4 -> 2.5966667 | K4: =Records!K4*$E4 -> 0 | L4: =Records!L4*$E4 -> 2.5966667 | M4: =Records!M4*$E4 -> 0 | N4: =Records!N4*$E4 -> 0 | ... V4: =Records!V4*$E4 -> 2.5966667
B5: =Records!B5 -> 45197 | C5: =Records!$C5 -> Pomax | D5: =SUMIF(Summary!$B$15:$B$31,C5,Summary!$D$15:$D$31) -> 6.4916667 | E5: =if(Records!E5=0,0,D5*Records!D5/Records!E5) -> 2.434375 | G5: =Records!G5*$E5 -> 2.434375 | H5: =Records!H5*$E5 -> 0 | I5: =Records!I5*$E5 -> 2.434375 | J5: =Records!J5*$E5 -> 2.434375 | K5: =Records!K5*$E5 -> 0 | L5: =Records!L5*$E5 -> 2.434375 | M5: =Records!M5*$E5 -> 0 | N5: =Records!N5*$E5 -> 0 | ... V5: =Records!V5*$E5 -> 2.434375
B6: =Records!B6 -> 45200 | C6: =Records!$C6 -> Pomax | D6: =SUMIF(Summary!$B$15:$B$31,C6,Summary!$D$15:$D$31) -> 6.4916667 | E6: =if(Records!E6=0,0,D6*Records!D6/Records!E6) -> 2.3606061 | G6: =Records!G6*$E6 -> 2.3606061 | H6: =Records!H6*$E6 -> 2.3606061 | I6: =Records!I6*$E6 -> 2.3606061 | J6: =Records!J6*$E6 -> 2.3606061 | K6: =Records!K6*$E6 -> 2.3606061 | L6: =Records!L6*$E6 -> 0 | M6: =Records!M6*$E6 -> 2.3606061 | N6: =Records!N6*$E6 -> 2.3606061 | ... V6: =Records!V6*$E6 -> 0
B7: =Records!B7 -> 45207 | C7: =Records!$C7 -> Pomax | D7: =SUMIF(Summary!$B$15:$B$31,C7,Summary!$D$15:$D$31) -> 6.4916667 | E7: =if(Records!E7=0,0,D7*Records!D7/Records!E7) -> 2.1638889 | G7: =Records!G7*$E7 -> 2.1638889 | H7: =Records!H7*$E7 -> 2.1638889 | I7: =Records!I7*$E7 -> 2.1638889 | J7: =Records!J7*$E7 -> 2.1638889 | K7: =Records!K7*$E7 -> 2.1638889 | L7: =Records!L7*$E7 -> 0 | M7: =Records!M7*$E7 -> 0 | N7: =Records!N7*$E7 -> 0 | ... V7: =Records!V7*$E7 -> 0
B8: =Records!B8 -> 45219 | C8: =Records!$C8 -> Pomax | D8: =SUMIF(Summary!$B$15:$B$31,C8,Summary!$D$15:$D$31) -> 6.4916667 | E8: =if(Records!E8=0,0,D8*Records!D8/Records!E8) -> 6.4916667 | G8: =Records!G8*$E8 -> 6.4916667 | H8: =Records!H8*$E8 -> 0 | I8: =Records!I8*$E8 -> 0 | J8: =Records!J8*$E8 -> 0 | K8: =Records!K8*$E8 -> 0 | L8: =Records!L8*$E8 -> 0 | M8: =Records!M8*$E8 -> 0 | N8: =Records!N8*$E8 -> 0 | ... V8: =Records!V8*$E8 -> 0
B9: =Records!B9 -> 45221 | C9: =Records!$C9 -> Pomax 2 | D9: =SUMIF(Summary!$B$15:$B$31,C9,Summary!$D$15:$D$31) -> 6.5341667 | E9: =if(Records!E9=0,0,D9*Records!D9/Records!E9) -> 3.6300926 | G9: =Records!G9*$E9 -> 3.6300926 | H9: =Records!H9*$E9 -> 3.6300926 | I9: =Records!I9*$E9 -> 0 | J9: =Records!J9*$E9 -> 3.6300926 | K9: =Records!K9*$E9 -> 3.6300926 | L9: =Records!L9*$E9 -> 0 | M9: =Records!M9*$E9 -> 0 | N9: =Records!N9*$E9 -> 3.6300926 | ... V9: =Records!V9*$E9 -> 0
B10: =Records!B10 -> 45228 | C10: =Records!$C10 -> Pomax 2 | D10: =SUMIF(Summary!$B$15:$B$31,C10,Summary!$D$15:$D$31) -> 6.5341667 | E10: =if(Records!E10=0,0,D10*Records!D10/Records!E10) -> 2.9040741 | G10: =Records!G10*$E10 -> 2.9040741 | H10: =Records!H10*$E10 -> 2.9040741 | I10: =Records!I10*$E10 -> 2.9040741 | J10: =Records!J10*$E10 -> 2.9040741 | K10: =Records!K10*$E10 -> 2.9040741 | L10: =Records!L10*$E10 -> 2.9040741 | M10: =Records!M10*$E10 -> 0 | N10: =Records!N10*$E10 -> 0 | ... V10: =Records!V10*$E10 -> 0
B11: =Records!B11 -> 45235 | C11: =Records!$C11 -> Pomax 2 | D11: =SUMIF(Summary!$B$15:$B$31,C11,Summary!$D$15:$D$31) -> 6.5341667 | E11: =if(Records!E11=0,0,D11*Records!D11/Records!E11) -> 1.96025 | G11: =Records!G11*$E11 -> 1.96025 | H11: =Records!H11*$E11 -> 1.96025 | I11: =Records!I11*$E11 -> 1.96025 | J11: =Records!J11*$E11 -> 1.96025 | K11: =Records!K11*$E11 -> 1.96025 | L11: =Records!L11*$E11 -> 1.96025 | M11: =Records!M11*$E11 -> 1.96025 | N11: =Records!N11*$E11 -> 0 | ... V11: =Records!V11*$E11 -> 0
B12: =Records!B12 -> 45629 | C12: =Records!$C12 -> DimG | D12: =SUMIF(Summary!$B$15:$B$31,C12,Summary!$D$15:$D$31) -> 7.1666667 | E12: =if(Records!E12=0,0,D12*Records!D12/Records!E12) -> 3.0714286 | G12: =Records!G12*$E12 -> 3.0714286 | H12: =Records!H12*$E12 -> 0 | I12: =Records!I12*$E12 -> 0 | J12: =Records!J12*$E12 -> 3.0714286 | K12: =Records!K12*$E12 -> 3.0714286 | L12: =Records!L12*$E12 -> 3.0714286 | M12: =Records!M12*$E12 -> 0 | N12: =Records!N12*$E12 -> 0 | ... V12: =Records!V12*$E12 -> 3.0714286
B13: =Records!B13 -> 45270 | C13: =Records!$C13 -> DimG | D13: =SUMIF(Summary!$B$15:$B$31,C13,Summary!$D$15:$D$31) -> 7.1666667 | E13: =if(Records!E13=0,0,D13*Records!D13/Records!E13) -> 3.5833333 | G13: =Records!G13*$E13 -> 3.5833333 | H13: =Records!H13*$E13 -> 3.5833333 | I13: =Records!I13*$E13 -> 3.5833333 | J13: =Records!J13*$E13 -> 3.5833333 | K13: =Records!K13*$E13 -> 3.5833333 | L13: =Records!L13*$E13 -> 3.5833333 | M13: =Records!M13*$E13 -> 0 | N13: =Records!N13*$E13 -> 0 | ... V13: =Records!V13*$E13 -> 0
B14: =Records!B14 -> 45277 | C14: =Records!$C14 -> DimG | D14: =SUMIF(Summary!$B$15:$B$31,C14,Summary!$D$15:$D$31) -> 7.1666667 | E14: =if(Records!E14=0,0,D14*Records!D14/Records!E14) -> 3.5833333 | G14: =Records!G14*$E14 -> 3.5833333 | H14: =Records!H14*$E14 -> 3.5833333 | I14: =Records!I14*$E14 -> 3.5833333 | J14: =Records!J14*$E14 -> 3.5833333 | K14: =Records!K14*$E14 -> 3.5833333 | L14: =Records!L14*$E14 -> 0 | M14: =Records!M14*$E14 -> 0 | N14: =Records!N14*$E14 -> 0 | ... V14: =Records!V14*$E14 -> 0
B15: =Records!B15 -> 45283 | C15: =Records!$C15 -> DimG | D15: =SUMIF(Summary!$B$15:$B$31,C15,Summary!$D$15:$D$31) -> 7.1666667 | E15: =if(Records!E15=0,0,D15*Records!D15/Records!E15) -> 3.0714286 | G15: =Records!G15*$E15 -> 3.0714286 | H15: =Records!H15*$E15 -> 3.0714286 | I15: =Records!I15*$E15 -> 3.0714286 | J15: =Records!J15*$E15 -> 3.0714286 | K15: =Records!K15*$E15 -> 3.0714286 | L15: =Records!L15*$E15 -> 3.0714286 | M15: =Records!M15*$E15 -> 0 | N15: =Records!N15*$E15 -> 0 | ... V15: =Records!V15*$E15 -> 0
... B62: =Records!B62 -> 45480 | C62: =Records!$C62 -> RSL S3 | D62: =SUMIF(Summary!$B$15:$B$31,C62,Summary!$D$15:$D$31) -> 7.1558333 | E62: =if(Records!E62=0,0,D62*Records!D62/Records!E62) -> 2.14675 | G62: =Records!G62*$E62 -> 2.14675 | H62: =Records!H62*$E62 -> 2.14675 | I62: =Records!I62*$E62 -> 0 | J62: =Records!J62*$E62 -> 2.14675 | K62: =Records!K62*$E62 -> 2.14675 | L62: =Records!L62*$E62 -> 2.14675 | M62: =Records!M62*$E62 -> 2.14675 | N62: =Records!N62*$E62 -> 0 | ... V62: =Records!V62*$E62 -> 2.14675
B63: =Records!B63 -> 45480 | C63: =Records!$C63 -> RSL S4 | D63: =SUMIF(Summary!$B$15:$B1000,C63,Summary!$D$15:$D1000) -> 7.1558333 | E63: =if(Records!E63=0,0,D63*Records!D63/Records!E63) -> 2.14675 | G63: =Records!G63*$E63 -> 2.14675 | H63: =Records!H63*$E63 -> 2.14675 | I63: =Records!I63*$E63 -> 0 | J63: =Records!J63*$E63 -> 2.14675 | K63: =Records!K63*$E63 -> 2.14675 | L63: =Records!L63*$E63 -> 2.14675 | M63: =Records!M63*$E63 -> 2.14675 | N63: =Records!N63*$E63 -> 0 | ... V63: =Records!V63*$E63 -> 2.14675
B64: =Records!B64 -> 45494 | C64: =Records!$C64 -> LM Orange | D64: =SUMIF(Summary!$B$15:$B1000,C64,Summary!$D$15:$D1000) -> 7.3216667 | E64: =if(Records!E64=0,0,D64*Records!D64/Records!E64) -> 3.6608333 | G64: =Records!G64*$E64 -> 3.6608333 | H64: =Records!H64*$E64 -> 3.6608333 | I64: =Records!I64*$E64 -> 0 | J64: =Records!J64*$E64 -> 3.6608333 | K64: =Records!K64*$E64 -> 3.6608333 | L64: =Records!L64*$E64 -> 7.3216667 | M64: =Records!M64*$E64 -> 0 | N64: =Records!N64*$E64 -> 0 | ... V64: =Records!V64*$E64 -> 3.6608333
B65: =Records!B65 -> 45600 | C65: =Records!$C65 -> LM DG | D65: =SUMIF(Summary!$B$15:$B1000,C65,Summary!$D$15:$D1000) -> 7.3216667 | E65: =if(Records!E65=0,0,D65*Records!D65/Records!E65) -> 3.1378571 | G65: =Records!G65*$E65 -> 3.1378571 | H65: =Records!H65*$E65 -> 3.1378571 | I65: =Records!I65*$E65 -> 0 | J65: =Records!J65*$E65 -> 0 | K65: =Records!K65*$E65 -> 3.1378571 | L65: =Records!L65*$E65 -> 3.1378571 | M65: =Records!M65*$E65 -> 0 | N65: =Records!N65*$E65 -> 0 | ... V65: =Records!V65*$E65 -> 3.1378571
B66: =Records!B66 -> 45515 | C66: =Records!$C66 -> LM DG | D66: =SUMIF(Summary!$B$15:$B1000,C66,Summary!$D$15:$D1000) -> 7.3216667 | E66: =if(Records!E66=0,0,D66*Records!D66/Records!E66) -> 3.9936364 | G66: =Records!G66*$E66 -> 15.974545 | H66: =Records!H66*$E66 -> 3.9936364 | I66: =Records!I66*$E66 -> 0 | J66: =Records!J66*$E66 -> 3.9936364 | K66: =Records!K66*$E66 -> 3.9936364 | L66: =Records!L66*$E66 -> 7.9872727 | M66: =Records!M66*$E66 -> 0 | N66: =Records!N66*$E66 -> 0 | ... V66: =Records!V66*$E66 -> 3.9936364
B67: =Records!B67 -> 45501 | C67: =Records!$C67 -> LM Orange | D67: =SUMIF(Summary!$B$15:$B1000,C67,Summary!$D$15:$D1000) -> 7.3216667 | E67: =if(Records!E67=0,0,D67*Records!D67/Records!E67) -> 5.1251667 | G67: =Records!G67*$E67 -> 5.1251667 | H67: =Records!H67*$E67 -> 5.1251667 | I67: =Records!I67*$E67 -> 0 | J67: =Records!J67*$E67 -> 5.1251667 | K67: =Records!K67*$E67 -> 5.1251667 | L67: =Records!L67*$E67 -> 5.1251667 | M67: =Records!M67*$E67 -> 0 | N67: =Records!N67*$E67 -> 0 | ... V67: =Records!V67*$E67 -> 5.1251667
B68: =Records!B68 -> 45522 | C68: =Records!$C68 -> LM Black | D68: =SUMIF(Summary!$B$15:$B1000,C68,Summary!$D$15:$D1000) -> 8.0716667 | E68: =if(Records!E68=0,0,D68*Records!D68/Records!E68) -> 7.0627083 | G68: =Records!G68*$E68 -> 7.0627083 | H68: =Records!H68*$E68 -> 0 | I68: =Records!I68*$E68 -> 7.0627083 | J68: =Records!J68*$E68 -> 7.0627083 | K68: =Records!K68*$E68 -> 7.0627083 | L68: =Records!L68*$E68 -> 7.0627083 | M68: =Records!M68*$E68 -> 0 | N68: =Records!N68*$E68 -> 0 | ... V68: =Records!V68*$E68 -> 7.0627083
B69: =Records!B69 -> 45529 | C69: =Records!$C69 -> LM DG | D69: =SUMIF(Summary!$B$15:$B1000,C69,Summary!$D$15:$D1000) -> 7.3216667 | E69: =if(Records!E69=0,0,D69*Records!D69/Records!E69) -> 2.745625 | G69: =Records!G69*$E69 -> 5.49125 | H69: =Records!H69*$E69 -> 0 | I69: =Records!I69*$E69 -> 0 | J69: =Records!J69*$E69 -> 2.745625 | K69: =Records!K69*$E69 -> 2.745625 | L69: =Records!L69*$E69 -> 0 | M69: =Records!M69*$E69 -> 0 | N69: =Records!N69*$E69 -> 0 | ... V69: =Records!V69*$E69 -> 2.745625
B70: =Records!B70 -> 45529 | C70: =Records!$C70 -> RSL S4 | D70: =SUMIF(Summary!$B$15:$B1000,C70,Summary!$D$15:$D1000) -> 7.1558333 | E70: =if(Records!E70=0,0,D70*Records!D70/Records!E70) -> 0.89447917 | G70: =Records!G70*$E70 -> 1.7889583 | H70: =Records!H70*$E70 -> 0 | I70: =Records!I70*$E70 -> 0 | J70: =Records!J70*$E70 -> 0.89447917 | K70: =Records!K70*$E70 -> 0.89447917 | L70: =Records!L70*$E70 -> 0 | M70: =Records!M70*$E70 -> 0 | N70: =Records!N70*$E70 -> 0 | ... V70: =Records!V70*$E70 -> 0.89447917
B71: =Records!B71 -> 45529 | C71: =Records!$C71 -> RCL T | D71: =SUMIF(Summary!$B$15:$B1000,C71,Summary!$D$15:$D1000) -> 5 | E71: =if(Records!E71=0,0,D71*Records!D71/Records!E71) -> 1.875 | G71: =Records!G71*$E71 -> 3.75 | H71: =Records!H71*$E71 -> 0 | I71: =Records!I71*$E71 -> 0 | J71: =Records!J71*$E71 -> 1.875 | K71: =Records!K71*$E71 -> 1.875 | L71: =Records!L71*$E71 -> 0 | M71: =Records!M71*$E71 -> 0 | N71: =Records!N71*$E71 -> 0 | ... V71: =Records!V71*$E71 -> 1.875
B72: =Records!B72 -> 45535 | C72: =Records!$C72 -> RCL BG | D72: =SUMIF(Summary!$B$15:$B1000,C72,Summary!$D$15:$D1000) -> 8.0083333 | E72: =if(Records!E72=0,0,D72*Records!D72/Records!E72) -> 16.016667 | G72: =Records!G72*$E72 -> 16.016667 | H72: =Records!H72*$E72 -> 0 | I72: =Records!I72*$E72 -> 0 | J72: =Records!J72*$E72 -> 0 | K72: =Records!K72*$E72 -> 0 | L72: =Records!L72*$E72 -> 0 | M72: =Records!M72*$E72 -> 0 | N72: =Records!N72*$E72 -> 0 | ... V72: =Records!V72*$E72 -> 0
B73: =Records!B73 -> 45543 | C73: =Records!$C73 -> RCL BG | D73: =SUMIF(Summary!$B$15:$B1000,C73,Summary!$D$15:$D1000) -> 8.0083333 | E73: =if(Records!E73=0,0,D73*Records!D73/Records!E73) -> 4.4490741 | G73: =Records!G73*$E73 -> 4.4490741 | H73: =Records!H73*$E73 -> 4.4490741 | I73: =Records!I73*$E73 -> 0 | J73: =Records!J73*$E73 -> 4.4490741 | K73: =Records!K73*$E73 -> 4.4490741 | L73: =Records!L73*$E73 -> 4.4490741 | M73: =Records!M73*$E73 -> 0 | N73: =Records!N73*$E73 -> 0 | ... V73: =Records!V73*$E73 -> 4.4490741
B74: =Records!B74 -> 45557 | C74: =Records!$C74 -> RCL BG2 | D74: =SUMIF(Summary!$B$15:$B1000,C74,Summary!$D$15:$D1000) -> 8.0083333 | E74: =if(Records!E74=0,0,D74*Records!D74/Records!E74) -> 2.6694444 | G74: =Records!G74*$E74 -> 2.6694444 | H74: =Records!H74*$E74 -> 0 | I74: =Records!I74*$E74 -> 0 | J74: =Records!J74*$E74 -> 2.6694444 | K74: =Records!K74*$E74 -> 2.6694444 | L74: =Records!L74*$E74 -> 2.6694444 | M74: =Records!M74*$E74 -> 0 | N74: =Records!N74*$E74 -> 2.6694444 | ... V74: =Records!V74*$E74 -> 2.6694444
B75: =Records!B75 -> 45564 | C75: =Records!$C75 -> RCL T | D75: =SUMIF(Summary!$B$15:$B1000,C75,Summary!$D$15:$D1000) -> 5 | E75: =if(Records!E75=0,0,D75*Records!D75/Records!E75) -> 0.55555556 | G75: =Records!G75*$E75 -> 0.55555556 | H75: =Records!H75*$E75 -> 0.55555556 | I75: =Records!I75*$E75 -> 0 | J75: =Records!J75*$E75 -> 0.55555556 | K75: =Records!K75*$E75 -> 0.55555556 | L75: =Records!L75*$E75 -> 0.55555556 | M75: =Records!M75*$E75 -> 0 | N75: =Records!N75*$E75 -> 0 | ... V75: =Records!V75*$E75 -> 0
B76: =Records!B76 -> 45564 | C76: =Records!$C76 -> LM Black | D76: =SUMIF(Summary!$B$15:$B1000,C76,Summary!$D$15:$D1000) -> 8.0716667 | E76: =if(Records!E76=0,0,D76*Records!D76/Records!E76) -> 0.89685185 | G76: =Records!G76*$E76 -> 0.89685185 | H76: =Records!H76*$E76 -> 0.89685185 | I76: =Records!I76*$E76 -> 0 | J76: =Records!J76*$E76 -> 0.89685185 | K76: =Records!K76*$E76 -> 0.89685185 | L76: =Records!L76*$E76 -> 0.89685185 | M76: =Records!M76*$E76 -> 0 | N76: =Records!N76*$E76 -> 0 | ... V76: =Records!V76*$E76 -> 0
B77: =Records!B77 -> 45564 | C77: =Records!$C77 -> RCL BG | D77: =SUMIF(Summary!$B$15:$B1000,C77,Summary!$D$15:$D1000) -> 8.0083333 | E77: =if(Records!E77=0,0,D77*Records!D77/Records!E77) -> 4.4490741 | G77: =Records!G77*$E77 -> 4.4490741 | H77: =Records!H77*$E77 -> 4.4490741 | I77: =Records!I77*$E77 -> 0 | J77: =Records!J77*$E77 -> 4.4490741 | K77: =Records!K77*$E77 -> 4.4490741 | L77: =Records!L77*$E77 -> 4.4490741 | M77: =Records!M77*$E77 -> 0 | N77: =Records!N77*$E77 -> 0 | ... V77: =Records!V77*$E77 -> 0
B78: =Records!B78 -> 45571 | C78: =Records!$C78 -> RCL BG2 | D78: =SUMIF(Summary!$B$15:$B1000,C78,Summary!$D$15:$D1000) -> 8.0083333 | E78: =if(Records!E78=0,0,D78*Records!D78/Records!E78) -> 3.5592593 | G78: =Records!G78*$E78 -> 3.5592593 | H78: =Records!H78*$E78 -> 3.5592593 | I78: =Records!I78*$E78 -> 0 | J78: =Records!J78*$E78 -> 3.5592593 | K78: =Records!K78*$E78 -> 3.5592593 | L78: =Records!L78*$E78 -> 3.5592593 | M78: =Records!M78*$E78 -> 0 | N78: =Records!N78*$E78 -> 0 | ... V78: =Records!V78*$E78 -> 3.5592593
B79: =Records!B79 -> 45578 | C79: =Records!$C79 -> RCL BG2 | D79: =SUMIF(Summary!$B$15:$B1000,C79,Summary!$D$15:$D1000) -> 8.0083333 | E79: =if(Records!E79=0,0,D79*Records!D79/Records!E79) -> 5.0052083 | G79: =Records!G79*$E79 -> 10.010417 | H79: =Records!H79*$E79 -> 0 | I79: =Records!I79*$E79 -> 0 | J79: =Records!J79*$E79 -> 5.0052083 | K79: =Records!K79*$E79 -> 5.0052083 | L79: =Records!L79*$E79 -> 0 | M79: =Records!M79*$E79 -> 0 | N79: =Records!N79*$E79 -> 0 | ... V79: =Records!V79*$E79 -> 0
B80: =Records!B80 -> 45578 | C80: =Records!$C80 -> LM Black | D80: =SUMIF(Summary!$B$15:$B1000,C80,Summary!$D$15:$D1000) -> 8.0716667 | E80: =if(Records!E80=0,0,D80*Records!D80/Records!E80) -> 1.0089583 | G80: =Records!G80*$E80 -> 2.0179167 | H80: =Records!H80*$E80 -> 0 | I80: =Records!I80*$E80 -> 0 | J80: =Records!J80*$E80 -> 1.0089583 | K80: =Records!K80*$E80 -> 1.0089583 | L80: =Records!L80*$E80 -> 0 | M80: =Records!M80*$E80 -> 0 | N80: =Records!N80*$E80 -> 0 | ... V80: =Records!V80*$E80 -> 0
B81: =Records!B81 -> 45585 | C81: =Records!$C81 -> LM DG2 | D81: =SUMIF(Summary!$B$15:$B1000,C81,Summary!$D$15:$D1000) -> 8.1325 | E81: =if(Records!E81=0,0,D81*Records!D81/Records!E81) -> 4.06625 | G81: =Records!G81*$E81 -> 4.06625 | H81: =Records!H81*$E81 -> 4.06625 | I81: =Records!I81*$E81 -> 0 | J81: =Records!J81*$E81 -> 4.06625 | K81: =Records!K81*$E81 -> 4.06625 | L81: =Records!L81*$E81 -> 0 | M81: =Records!M81*$E81 -> 0 | N81: =Records!N81*$E81 -> 0 | ... V81: =Records!V81*$E81 -> 0
B82: =Records!B82 -> 45599 | C82: =Records!$C82 -> LM DG2 | D82: =SUMIF(Summary!$B$15:$B1000,C82,Summary!$D$15:$D1000) -> 8.1325 | E82: =if(Records!E82=0,0,D82*Records!D82/Records!E82) -> 2.033125 | G82: =Records!G82*$E82 -> 4.06625 | H82: =Records!H82*$E82 -> 2.033125 | I82: =Records!I82*$E82 -> 0 | J82: =Records!J82*$E82 -> 2.033125 | K82: =Records!K82*$E82 -> 2.033125 | L82: =Records!L82*$E82 -> 0 | M82: =Records!M82*$E82 -> 2.033125 | N82: =Records!N82*$E82 -> 0 | ... V82: =Records!V82*$E82 -> 0
B83: =Records!B83 -> 45599 | C83: =Records!$C83 -> LM Black | D83: =SUMIF(Summary!$B$15:$B1000,C83,Summary!$D$15:$D1000) -> 8.0716667 | E83: =if(Records!E83=0,0,D83*Records!D83/Records!E83) -> 3.026875 | G83: =Records!G83*$E83 -> 6.05375 | H83: =Records!H83*$E83 -> 3.026875 | I83: =Records!I83*$E83 -> 0 | J83: =Records!J83*$E83 -> 3.026875 | K83: =Records!K83*$E83 -> 3.026875 | L83: =Records!L83*$E83 -> 0 | M83: =Records!M83*$E83 -> 3.026875 | N83: =Records!N83*$E83 -> 0 | ... V83: =Records!V83*$E83 -> 0
B84: =Records!B84 -> 45606 | C84: =Records!$C84 -> RSL S5 | D84: =SUMIF(Summary!$B$15:$B1000,C84,Summary!$D$15:$D1000) -> 8.2308333 | E84: =if(Records!E84=0,0,D84*Records!D84/Records!E84) -> 3.2923333 | G84: =Records!G84*$E84 -> 3.2923333 | H84: =Records!H84*$E84 -> 3.2923333 | I84: =Records!I84*$E84 -> 0 | J84: =Records!J84*$E84 -> 3.2923333 | K84: =Records!K84*$E84 -> 3.2923333 | L84: =Records!L84*$E84 -> 3.2923333 | M84: =Records!M84*$E84 -> 3.2923333 | N84: =Records!N84*$E84 -> 0 | ... V84: =Records!V84*$E84 -> 3.2923333
B85: =Records!B85 -> 45620 | C85: =Records!$C85 -> RSL S5 | D85: =SUMIF(Summary!$B$15:$B1000,C85,Summary!$D$15:$D1000) -> 8.2308333 | E85: =if(Records!E85=0,0,D85*Records!D85/Records!E85) -> 5.1442708 | G85: =Records!G85*$E85 -> 5.1442708 | H85: =Records!H85*$E85 -> 5.1442708 | I85: =Records!I85*$E85 -> 0 | J85: =Records!J85*$E85 -> 0 | K85: =Records!K85*$E85 -> 5.1442708 | L85: =Records!L85*$E85 -> 5.1442708 | M85: =Records!M85*$E85 -> 5.1442708 | N85: =Records!N85*$E85 -> 0 | ... V85: =Records!V85*$E85 -> 0
B86: =Records!B86 -> 45626 | C86: =Records!$C86 -> RSL S5 | D86: =SUMIF(Summary!$B$15:$B1000,C86,Summary!$D$15:$D1000) -> 8.2308333 | E86: =if(Records!E86=0,0,D86*Records!D86/Records!E86) -> 2.46925 | G86: =Records!G86*$E86 -> 2.46925 | H86: =Records!H86*$E86 -> 2.46925 | I86: =Records!I86*$E86 -> 0 | J86: =Records!J86*$E86 -> 2.46925 | K86: =Records!K86*$E86 -> 2.46925 | L86: =Records!L86*$E86 -> 2.46925 | M86: =Records!M86*$E86 -> 0 | N86: =Records!N86*$E86 -> 0 | ... V86: =Records!V86*$E86 -> 2.46925
B87: =Records!B87 -> 45626 | C87: =Records!$C87 -> LM DG2 | D87: =SUMIF(Summary!$B$15:$B1000,C87,Summary!$D$15:$D1000) -> 8.1325 | E87: =if(Records!E87=0,0,D87*Records!D87/Records!E87) -> 3.253 | G87: =Records!G87*$E87 -> 3.253 | H87: =Records!H87*$E87 -> 3.253 | I87: =Records!I87*$E87 -> 0 | J87: =Records!J87*$E87 -> 3.253 | K87: =Records!K87*$E87 -> 3.253 | L87: =Records!L87*$E87 -> 3.253 | M87: =Records!M87*$E87 -> 0 | N87: =Records!N87*$E87 -> 0 | ... V87: =Records!V87*$E87 -> 3.253
B88: =Records!B88 -> 45633 | C88: =Records!$C88 -> RSL S6 | D88: =SUMIF(Summary!$B$15:$B1000,C88,Summary!$D$15:$D1000) -> 8.2308333 | E88: =if(Records!E88=0,0,D88*Records!D88/Records!E88) -> 6.173125 | G88: =Records!G88*$E88 -> 6.173125 | H88: =Records!H88*$E88 -> 0 | I88: =Records!I88*$E88 -> 0 | J88: =Records!J88*$E88 -> 6.173125 | K88: =Records!K88*$E88 -> 6.173125 | L88: =Records!L88*$E88 -> 6.173125 | M88: =Records!M88*$E88 -> 0 | N88: =Records!N88*$E88 -> 0 | ... V88: =Records!V88*$E88 -> 0
...

Sheet Total2
B1: Pay | C1: Total | D1: Total | E1: Total | F1: Total | G1: Total | H1: Total | I1: Total | J1: Total | K1: Total | M1: Pay | N1: Amount | O1: Status
B2: Total | C2: 77.9 | D2: 78.41 | E2: 86 | F2: 76.67 | G2: 69.36 | H2: 105 | I2: 75 | J2: =SUM(J3:J18) -> 25.276204 | K2: =SUM(C2:J2) -> 593.6162 | N2: =SUM(N3:N18) -> 593.6162
B3: Poi | C3: 16.047203 | D3: 8.4944167 | E3: 13.309524 | F3: 9.5431839 | G3: 14.622024 | H3: 11.350694 | I3: 10.297619 | M3: Poi | N3: =SUM(C3:J3) -> 83.664665 | O3: TRUE
B4: KC | C4: 9.5555366 | D4: 8.4944167 | E4: 13.309524 | F4: 9.5431839 | G4: 8.8420238 | H4: 11.350694 | I4: 10.297619 | M4: KC | N4: =SUM(C4:J4) -> 71.392998 | O4: TRUE
B5: HX | C5: 10.062083 | D5: 4.8643241 | E5: 12.797619 | F5: 4.4724167 | G5: 7.4658333 | H5: 13.78125 | I5: 12.380952 | M5: HX | N5: =SUM(C5:J5) -> 65.824479 | O5: TRUE
B6: ZT | C6: 4.5244949 | D6: 8.4944167 | E6: 10.238095 | F6: 9.5431839 | G6: 6.9153571 | H6: 13.100694 | I6: 8.8392857 | M6: ZT | N6: =SUM(C6:J6) -> 61.655528 | O6: TRUE
B7: YZ | C7: 6.9588699 | D7: 4.8643241 | E7: 10.238095 | F7: 6.3486005 | G7: 8.8420238 | H7: 15.725694 | I7: 5.8333333 | M7: YZ | N7: =SUM(C7:J7) -> 58.810941 | O7: TRUE
B8: CJ | C8: 4.5244949 | D8: 8.4944167 | E8: 13.309524 | F8: 9.5431839 | G8: 6.9153571 | H8: 8.0694444 | I8: 5.0892857 | M8: CJ | N8: =SUM(C8:J8) -> 55.945707 | O8: TRUE
B9: KY | C9: 6.9588699 | D9: 8.4944167 | E9: 3.0714286 | F9: 9.5431839 | G9: 6.9153571 | H9: 10.256944 | I9: 6.6517857 | M9: KY | N9: =SUM(C9:J9) -> 51.891986 | O9: TRUE
B10: YL | C10: 4.9572727 | D10: 8.4944167 | E10: 6.6547619 | F10: 5.8922315 | G10: 3.3028571 | H10: 10.256944 | I10: 6.6517857 | M10: YL | N10: =SUM(C10:J10) -> 46.21027 | O10: TRUE
B11: Matthew | C11: 4.7949811 | D11: 8.4944167 | E11: 3.0714286 | F11: 6.3486005 | G11: 0 | H11: 1.9444444 | I11: 0 | M11: Matthew | N11: =SUM(C11:J11) -> 24.653871 | O11: TRUE
B12: Hau Jin | C12: 0 | D12: 0 | E12: 0 | F12: 0 | G12: 1.9266667 | H12: 3.28125 | I12: 5.2083333 | J12: 13.255744 | M12: Hau Jin | N12: =SUM(C12:J12) -> 23.671994 | O12: TRUE
B13: LW | C13: 2.3606061 | D13: 3.6300926 | E13: 0 | F13: 4.6143981 | G13: 0 | H13: 1.9444444 | I13: 0 | J13: 7.4502937 | M13: LW | N13: =SUM(C13:J13) -> 19.999835 | O13: TRUE
B14: JZ | C14: 2.3606061 | D14: 1.96025 | E14: 0 | F14: 1.2778333 | G14: 3.6125 | H14: 2.84375 | I14: 2.1875 | M14: JZ | N14: =SUM(C14:J14) -> 14.242439 | O14: TRUE
B15: YX | C15: 4.7949811 | D15: 0 | E15: 0 | F15: 0 | G15: 0 | H15: 1.09375 | I15: 1.5625 | M15: YX | N15: =SUM(C15:J15) -> 7.4512311 | O15: TRUE
B16: Jit Loong | C16: 0 | D16: 3.6300926 | E16: 0 | F16: 0 | G16: 0 | H16: 0 | I16: 0 | J16: 3.204 | M16: Jit Loong | N16: =SUM(C16:J16) -> 6.8340926 | O16: TRUE
B17: Kit Liang | C17: 0 | D17: 0 | E17: 0 | F17: 0 | G17: 0 | H17: 0 | I17: 0 | J17: 1.3661667 | M17: Kit Liang | N17: =SUM(C17:J17) -> 1.3661667 | O17: TRUE
B18: ZL | C18: 0 | D18: 0 | E18: 0 | F18: 0 | G18: 0 | H18: 0 | I18: 0 | M18: ZZ | N18: =SUM(C18:J18) -> 0 | O18: TRUE
C19: Pomax (Poi) | D19: Pomax 2 (Poi) | E19: DimG (Poi) | F19: RSL C (Poi) | G19: Sealion (Poi) | H19: AS50 (Poi) | I19: Felet (Poi) | J19: Previous
A21: 45411 | B21: Pay | C21: Total | D21: Total | E21: Total | F21: Total | G21: Total | H21: Total | I21: Total | K21: Total | M21: Pay | N21: Amount | O21: Status
B22: Total | C22: =SUM(C23:C38) -> 76.41 | D22: =SUM(D23:D38) -> 80 | E22: =SUM(E23:E38) -> 69.36 | F22: =SUM(F23:F38) -> 75.397864 | G22: =SUM(G23:G38) -> 50.5 | H22: =SUM(H23:H38) -> 74.98 | I22: =SUM(I23:I38) -> 74.98 | K22: =SUM(C22:I22) -> 501.62786 | N22: =SUM(N23:N38) -> 501.62786
B23: Poi | C23: 10.119777 | D23: 10.582011 | E23: 23.8425 | F23: 7.1963182 | H23: 10.860198 | I23: 7.9603136 | M23: Poi | N23: =SUM(C23:I23) -> 70.561118 | O23: TRUE
B24: ZT | C24: 5.5715625 | D24: 10.582011 | E24: 6.5025 | F24: 7.1963182 | H24: 7.2897222 | I24: 7.9603136 | M24: ZT | N24: =SUM(C24:I24) -> 45.102427 | O24: TRUE
B25: YZ | C25: 6.9360268 | D25: 0 | E25: 6.5025 | F25: 7.1963182 | H25: 0 | I25: 0 | M25: YZ | N25: =SUM(C25:I25) -> 20.634845 | O25: TRUE
B26: KC | C26: 10.119777 | D26: 10.582011 | E26: 6.5025 | F26: 7.1963182 | H26: 10.860198 | I26: 7.9603136 | M26: KC | N26: =SUM(C26:I26) -> 53.221118 | O26: TRUE
B27: CJ | C27: 7.7319643 | D27: 10.582011 | E27: 6.5025 | F27: 7.1963182 | H27: 10.860198 | I27: 7.9603136 | M27: CJ | N27: =SUM(C27:I27) -> 50.833305 | O27: TRUE
B28: HX | C28: 5.5715625 | D28: 10.582011 | E28: 6.5025 | F28: 10.97 | H28: 6.6946429 | I28: 7.1792719 | M28: HX | N28: =SUM(C28:I28) -> 47.499988 | O28: TRUE
B29: JZ | C29: 2.3878125 | D29: 0 | E29: 0 | F29: 0 | H29: 0 | I29: 0 | M29: JZ | N29: =SUM(C29:I29) -> 2.3878125 | O29: TRUE
B30: LW | C30: 0 | D30: 6.7724868 | E30: 0 | F30: 3.4268182 | G30: 20 | H30: 0 | I30: 2.8401515 | M30: LW | N30: =SUM(C30:I30) -> 33.039456 | O30: TRUE
B31: KY | C31: 7.7319643 | D31: 6.7724868 | E31: 6.5025 | F31: 7.1963182 | H31: 10.860198 | I31: 7.9603136 | M31: KY | N31: =SUM(C31:I31) -> 47.023781 | O31: TRUE
B32: Jit Loong | C32: 0 | D32: 0 | E32: 0 | F32: 0 | G32: 6.83 | H32: 0 | I32: 2.777037 | M32: Jit Loong | N32: =SUM(C32:I32) -> 9.607037 | O32: TRUE
B33: Matthew | C33: 0 | D33: 0 | E33: 0 | F33: 0 | H33: 3.5704762 | I33: 0 | M33: Matthew | N33: =SUM(C33:I33) -> 3.5704762 | O33: TRUE
B34: Hau Jin | C34: 10.119777 | D34: 2.962963 | E34: 0 | F34: 3.4268182 | G34: 23.67 | H34: 3.1241667 | I34: 5.1832765 | M34: Hau Jin | N34: =SUM(C34:I34) -> 48.487001 | O34: TRUE
B35: Kit Liang | C35: 4.5482143 | D35: 0 | E35: 0 | F35: 0 | H35: 0 | I35: 0 | M35: Kit Liang | N35: =SUM(C35:I35) -> 4.5482143 | O35: TRUE
B36: YL | C36: 3.18375 | D36: 10.582011 | E36: 6.5025 | F36: 7.1963182 | H36: 10.860198 | I36: 7.9603136 | M36: YL | N36: =SUM(C36:I36) -> 46.285091 | O36: TRUE
B37: YX | C37: 2.3878125 | D37: 0 | E37: 0 | F37: 0 | H37: 0 | I37: 2.8401515 | M37: YX | N37: =SUM(C37:I37) -> 5.227964 | O37: TRUE
B38: ZZ | C38: 0 | D38: 0 | E38: 0 | F38: 7.2 | H38: 0 | I38: 6.3982302 | M38: ZZ | N38: =SUM(C38:I38) -> 13.59823 | O38: TRUE
C39: RSL S | D39: RSL S2 | E39: Protech Plat | F39: RSL S Stream | G39: Previous | H39: Protech Plat 2 | I39: Protech Plat 3
A41: 45535 | B41: Pay | C41: Total | D41: Total | E41: Total | F41: Total | G41: Total | H41: Total | I41: Total | K41: Total | M41: Pay | N41: Amount | O41: Status
B42: Total | C42: =SUM(C43:C58) -> 68.134833 | D42: =SUM(D43:D58) -> 85.87 | E42: =SUM(E43:E58) -> 87.86 | F42: =SUM(F43:F58) -> 85.87 | G42: =SUM(G43:G58) -> 87.86 | H42: =SUM(H43:H58) -> 50 | I42: =SUM(I43:I58) -> 96.1 | K42: =SUM(C42:I42) -> 561.69483 | N42: =SUM(N43:N58) -> 561.69483
...

Sheet Felet (Poi)
A1: Tube price | B1: 75 | D1: Players | E1: 45340 | F1: 45343 | O1: Pay | P1: Total | S1: Frequency
A2: No. of ball | B2: 12 | D2: Poi | E2: 1 | F2: 1 | O2: =D2 -> Poi | P2: =SUM(E24:M24) -> 2.7083333 | S2: =COUNT(E2:M2) -> 2
A3: Ball price | B3: =B1/B2 -> 6.25 | D3: ZT | F3: 2 | O3: =D3 -> ZT | P3: =SUM(E25:M25) -> 1.25 | S3: =COUNT(E3:M3) -> 1
D4: YZ | E4: 1 | F4: 1 | O4: =D4 -> YZ | P4: =SUM(E26:M26) -> 2.7083333 | S4: =COUNT(E4:M4) -> 2
A5: Tube Holder | B5: Poi | D5: KC | E5: 1 | F5: 1 | O5: =D5 -> KC | P5: =SUM(E27:M27) -> 2.7083333 | S5: =COUNT(E5:M5) -> 2
D6: CJ | F6: 1 | O6: =D6 -> CJ | P6: =SUM(E28:M28) -> 0.625 | S6: =COUNT(E6:M6) -> 1
A7: Balls left | B7: =B2-SUM(E20:M20) -> 9 | D7: HX | E7: 2 | F7: 1 | O7: =D7 -> HX | P7: =SUM(E29:M29) -> 4.7916667 | S7: =COUNT(E7:M7) -> 2
D8: JZ | F8: 1 | O8: =D8 -> JZ | P8: =SUM(E30:M30) -> 0.625 | S8: =COUNT(E8:M8) -> 1
D9: LW | O9: =D9 -> LW | P9: =SUM(E31:M31) -> 0 | S9: =COUNT(E9:M9) -> 0
D10: KY | F10: 1 | O10: =D10 -> KY | P10: =SUM(E32:M32) -> 0.625 | S10: =COUNT(E10:M10) -> 1
D11: Jit Loong | O11: =D11 -> Jit Loong | P11: =SUM(E33:M33) -> 0 | S11: =COUNT(E11:M11) -> 0
D12: Matthew | O12: =D12 -> Matthew | P12: =SUM(E34:M34) -> 0 | S12: =COUNT(E12:M12) -> 0
D13: Hau Jin | E13: 1 | O13: =D13 -> Hau Jin | P13: =SUM(E35:M35) -> 2.0833333 | S13: =COUNT(E13:M13) -> 1
D14: Kit Liang | O14: =D14 -> Kit Liang | P14: =SUM(E36:M36) -> 0 | S14: =COUNT(E14:M14) -> 0
D15: YL | F15: 1 | O15: =D15 -> YL | P15: =SUM(E37:M37) -> 0.625 | S15: =COUNT(E15:M15) -> 1
D16: YX | O16: =D16 -> YX | P16: =SUM(E38:M38) -> 0 | S16: =COUNT(E16:M16) -> 0
D17: ZL | O17: =D17 -> ZL | P17: =SUM(E39:M39) -> 0 | S17: =COUNT(E17:M17) -> 0
P18: =SUM(P2:P17) -> 18.75
D19: User | E19: =SUM(E2:E17) -> 6 | F19: =SUM(F2:F17) -> 10 | G19: =SUM(G2:G17) -> 0 | H19: =SUM(H2:H17) -> 0 | I19: =SUM(I2:I17) -> 0 | J19: =SUM(J2:J17) -> 0 | K19: =SUM(K2:K17) -> 0 | L19: =SUM(L2:L17) -> 0 | M19: =SUM(M2:M17) -> 0
D20: Ball usage | E20: 2 | F20: 1
D21: Weightage price | E21: =IF(E19=0, 0, $B$3*E20/E19) -> 2.0833333 | F21: =IF(F19=0, 0, $B$3*F20/F19) -> 0.625 | G21: =IF(G19=0, 0, $B$3*G20/G19) -> 0 | H21: =IF(H19=0, 0, $B$3*H20/H19) -> 0 | I21: =IF(I19=0, 0, $B$3*I20/I19) -> 0 | J21: =IF(J19=0, 0, $B$3*J20/J19) -> 0 | K21: =IF(K19=0, 0, $B$3*K20/K19) -> 0 | L21: =IF(L19=0, 0, $B$3*L20/L19) -> 0 | M21: =IF(M19=0, 0, $B$3*M20/M19) -> 0
D23: Pay | E23: =E1 -> 45340 | F23: =F1 -> 45343 | G23: =G1 | H23: =H1 | I23: =I1 | J23: =J1 | K23: =K1 | L23: =L1 | M23: =M1
D24: =D2 -> Poi | E24: =E2*$E$21 -> 2.0833333 | F24: =F2*$F$21 -> 0.625 | G24: =G2*G$21 -> 0 | H24: =H2*H$21 -> 0 | I24: =I2*I$21 -> 0 | J24: =J2*J$21 -> 0 | K24: =K2*K$21 -> 0 | L24: =L2*L$21 -> 0 | M24: =M2*M$21 -> 0
D25: =D3 -> ZT | E25: =E3*$E$21 -> 0 | F25: =F3*$F$21 -> 1.25 | G25: =G3*G$21 -> 0 | H25: =H3*H$21 -> 0 | I25: =I3*I$21 -> 0 | J25: =J3*J$21 -> 0 | K25: =K3*K$21 -> 0 | L25: =L3*L$21 -> 0 | M25: =M3*M$21 -> 0
D26: =D4 -> YZ | E26: =E4*$E$21 -> 2.0833333 | F26: =F4*$F$21 -> 0.625 | G26: =G4*G$21 -> 0 | H26: =H4*H$21 -> 0 | I26: =I4*I$21 -> 0 | J26: =J4*J$21 -> 0 | K26: =K4*K$21 -> 0 | L26: =L4*L$21 -> 0 | M26: =M4*M$21 -> 0
D27: =D5 -> KC | E27: =E5*$E$21 -> 2.0833333 | F27: =F5*$F$21 -> 0.625 | G27: =G5*G$21 -> 0 | H27: =H5*H$21 -> 0 | I27: =I5*I$21 -> 0 | J27: =J5*J$21 -> 0 | K27: =K5*K$21 -> 0 | L27: =L5*L$21 -> 0 | M27: =M5*M$21 -> 0
D28: =D6 -> CJ | E28: =E6*$E$21 -> 0 | F28: =F6*$F$21 -> 0.625 | G28: =G6*G$21 -> 0 | H28: =H6*H$21 -> 0 | I28: =I6*I$21 -> 0 | J28: =J6*J$21 -> 0 | K28: =K6*K$21 -> 0 | L28: =L6*L$21 -> 0 | M28: =M6*M$21 -> 0
D29: =D7 -> HX | E29: =E7*$E$21 -> 4.1666667 | F29: =F7*$F$21 -> 0.625 | G29: =G7*G$21 -> 0 | H29: =H7*H$21 -> 0 | I29: =I7*I$21 -> 0 | J29: =J7*J$21 -> 0 | K29: =K7*K$21 -> 0 | L29: =L7*L$21 -> 0 | M29: =M7*M$21 -> 0
D30: =D8 -> JZ | E30: =E8*$E$21 -> 0 | F30: =F8*$F$21 -> 0.625 | G30: =G8*G$21 -> 0 | H30: =H8*H$21 -> 0 | I30: =I8*I$21 -> 0 | J30: =J8*J$21 -> 0 | K30: =K8*K$21 -> 0 | L30: =L8*L$21 -> 0 | M30: =M8*M$21 -> 0
D31: =D9 -> LW | E31: =E9*$E$21 -> 0 | F31: =F9*$F$21 -> 0 | G31: =G9*G$21 -> 0 | H31: =H9*H$21 -> 0 | I31: =I9*I$21 -> 0 | J31: =J9*J$21 -> 0 | K31: =K9*K$21 -> 0 | L31: =L9*L$21 -> 0 | M31: =M9*M$21 -> 0
D32: =D10 -> KY | E32: =E10*$E$21 -> 0 | F32: =F10*$F$21 -> 0.625 | G32: =G10*G$21 -> 0 | H32: =H10*H$21 -> 0 | I32: =I10*I$21 -> 0 | J32: =J10*J$21 -> 0 | K32: =K10*K$21 -> 0 | L32: =L10*L$21 -> 0 | M32: =M10*M$21 -> 0
D33: =D11 -> Jit Loong | E33: =E11*$E$21 -> 0 | F33: =F11*$F$21 -> 0 | G33: =G11*G$21 -> 0 | H33: =H11*H$21 -> 0 | I33: =I11*I$21 -> 0 | J33: =J11*J$21 -> 0 | K33: =K11*K$21 -> 0 | L33: =L11*L$21 -> 0 | M33: =M11*M$21 -> 0
D34: =D12 -> Matthew | E34: =E12*$E$21 -> 0 | F34: =F12*$F$21 -> 0 | G34: =G12*G$21 -> 0 | H34: =H12*H$21 -> 0 | I34: =I12*I$21 -> 0 | J34: =J12*J$21 -> 0 | K34: =K12*K$21 -> 0 | L34: =L12*L$21 -> 0 | M34: =M12*M$21 -> 0
D35: =D13 -> Hau Jin | E35: =E13*$E$21 -> 2.0833333 | F35: =F13*$F$21 -> 0 | G35: =G13*G$21 -> 0 | H35: =H13*H$21 -> 0 | I35: =I13*I$21 -> 0 | J35: =J13*J$21 -> 0 | K35: =K13*K$21 -> 0 | L35: =L13*L$21 -> 0 | M35: =M13*M$21 -> 0
... D39: =D17 -> ZL | E39: =E17*$E$21 -> 0 | F39: =F17*$F$21 -> 0 | G39: =G17*G$21 -> 0 | H39: =H17*H$21 -> 0 | I39: =I17*I$21 -> 0 | J39: =J17*J$21 -> 0 | K39: =K17*K$21 -> 0 | L39: =L17*L$21 -> 0 | M39: =M17*M$21 -> 0
D41: Sum | E41: =SUM(E24:E39) -> 12.5 | F41: =SUM(F24:F39) -> 6.25 | G41: =SUM(G24:G39) -> 0 | H41: =SUM(H24:H39) -> 0 | I41: =SUM(I24:I39) -> 0 | J41: =SUM(J24:J39) -> 0 | K41: =SUM(K24:K39) -> 0 | L41: =SUM(L24:L39) -> 0 | M41: =SUM(M24:M39) -> 0

Sheet AS50 (Poi)
A1: Tube price | B1: 105 | D1: Players | E1: 45221 | F1: 45657 | G1: 45343 | O1: Pay | P1: Total | S1: Frequency
A2: No. of ball | B2: 12 | D2: Poi | E2: 1 | F2: 1 | G2: 1 | O2: =D2 -> Poi | P2: =SUM(E24:M24) -> 8.0694444 | S2: =COUNT(E2:M2) -> 3
A3: Ball price | B3: =B1/B2 -> 8.75 | D3: ZT | E3: 1 | F3: 1 | G3: 2 | O3: =D3 -> ZT | P3: =SUM(E25:M25) -> 9.8194444 | S3: =COUNT(E3:M3) -> 3
D4: YZ | E4: 1 | F4: 2 | G4: 1 | O4: =D4 -> YZ | P4: =SUM(E26:M26) -> 12.444444 | S4: =COUNT(E4:M4) -> 3
A5: Tube Holder | B5: Poi | D5: KC | E5: 1 | F5: 1 | G5: 1 | O5: =D5 -> KC | P5: =SUM(E27:M27) -> 8.0694444 | S5: =COUNT(E5:M5) -> 3
D6: CJ | E6: 1 | F6: 1 | G6: 1 | O6: =D6 -> CJ | P6: =SUM(E28:M28) -> 8.0694444 | S6: =COUNT(E6:M6) -> 3
A7: Balls left | B7: =B2-SUM(E20:M20) -> 3 | D7: HX | F7: 2 | G7: 1 | O7: =D7 -> HX | P7: =SUM(E29:M29) -> 10.5 | S7: =COUNT(E7:M7) -> 2
D8: JZ | G8: 1 | O8: =D8 -> JZ | P8: =SUM(E30:M30) -> 1.75 | S8: =COUNT(E8:M8) -> 1
D9: LW | E9: 1 | O9: =D9 -> LW | P9: =SUM(E31:M31) -> 1.9444444 | S9: =COUNT(E9:M9) -> 1
D10: KY | E10: 1 | F10: 1 | G10: 1 | O10: =D10 -> KY | P10: =SUM(E32:M32) -> 8.0694444 | S10: =COUNT(E10:M10) -> 3
D11: Jit Loong | O11: =D11 -> Jit Loong | P11: =SUM(E33:M33) -> 0 | S11: =COUNT(E11:M11) -> 0
D12: Matthew | E12: 1 | O12: =D12 -> Matthew | P12: =SUM(E34:M34) -> 1.9444444 | S12: =COUNT(E12:M12) -> 1
D13: Hau Jin | O13: =D13 -> Hau Jin | P13: =SUM(E35:M35) -> 0 | S13: =COUNT(E13:M13) -> 0
D14: Kit Liang | O14: =D14 -> Kit Liang | P14: =SUM(E36:M36) -> 0 | S14: =COUNT(E14:M14) -> 0
D15: YL | E15: 1 | F15: 1 | G15: 1 | O15: =D15 -> YL | P15: =SUM(E37:M37) -> 8.0694444 | S15: =COUNT(E15:M15) -> 3
D16: YX | O16: =D16 -> YX | P16: =SUM(E38:M38) -> 0 | S16: =COUNT(E16:M16) -> 0
D17: ZL | O17: =D17 -> ZL | P17: =SUM(E39:M39) -> 0 | S17: =COUNT(E17:M17) -> 0
P18: =SUM(P2:P17) -> 78.75
D19: User | E19: =SUM(E2:E17) -> 9 | F19: =SUM(F2:F17) -> 10 | G19: =SUM(G2:G17) -> 10 | H19: =SUM(H2:H17) -> 0 | I19: =SUM(I2:I17) -> 0 | J19: =SUM(J2:J17) -> 0 | K19: =SUM(K2:K17) -> 0 | L19: =SUM(L2:L17) -> 0 | M19: =SUM(M2:M17) -> 0
D20: Ball usage | E20: 2 | F20: 5 | G20: 2
D21: Weightage price | E21: =IF(E19=0, 0, $B$3*E20/E19) -> 1.9444444 | F21: =IF(F19=0, 0, $B$3*F20/F19) -> 4.375 | G21: =IF(G19=0, 0, $B$3*G20/G19) -> 1.75 | H21: =IF(H19=0, 0, $B$3*H20/H19) -> 0 | I21: =IF(I19=0, 0, $B$3*I20/I19) -> 0 | J21: =IF(J19=0, 0, $B$3*J20/J19) -> 0 | K21: =IF(K19=0, 0, $B$3*K20/K19) -> 0 | L21: =IF(L19=0, 0, $B$3*L20/L19) -> 0 | M21: =IF(M19=0, 0, $B$3*M20/M19) -> 0
D23: Pay | E23: =E1 -> 45221 | F23: =F1 -> 45657 | G23: =G1 -> 45343 | H23: =H1 | I23: =I1 | J23: =J1 | K23: =K1 | L23: =L1 | M23: =M1
D24: =D2 -> Poi | E24: =E2*$E$21 -> 1.9444444 | F24: =F2*$F$21 -> 4.375 | G24: =G2*G$21 -> 1.75 | H24: =H2*H$21 -> 0 | I24: =I2*I$21 -> 0 | J24: =J2*J$21 -> 0 | K24: =K2*K$21 -> 0 | L24: =L2*L$21 -> 0 | M24: =M2*M$21 -> 0
D25: =D3 -> ZT | E25: =E3*$E$21 -> 1.9444444 | F25: =F3*$F$21 -> 4.375 | G25: =G3*G$21 -> 3.5 | H25: =H3*H$21 -> 0 | I25: =I3*I$21 -> 0 | J25: =J3*J$21 -> 0 | K25: =K3*K$21 -> 0 | L25: =L3*L$21 -> 0 | M25: =M3*M$21 -> 0
D26: =D4 -> YZ | E26: =E4*$E$21 -> 1.9444444 | F26: =F4*$F$21 -> 8.75 | G26: =G4*G$21 -> 1.75 | H26: =H4*H$21 -> 0 | I26: =I4*I$21 -> 0 | J26: =J4*J$21 -> 0 | K26: =K4*K$21 -> 0 | L26: =L4*L$21 -> 0 | M26: =M4*M$21 -> 0
D27: =D5 -> KC | E27: =E5*$E$21 -> 1.9444444 | F27: =F5*$F$21 -> 4.375 | G27: =G5*G$21 -> 1.75 | H27: =H5*H$21 -> 0 | I27: =I5*I$21 -> 0 | J27: =J5*J$21 -> 0 | K27: =K5*K$21 -> 0 | L27: =L5*L$21 -> 0 | M27: =M5*M$21 -> 0
D28: =D6 -> CJ | E28: =E6*$E$21 -> 1.9444444 | F28: =F6*$F$21 -> 4.375 | G28: =G6*G$21 -> 1.75 | H28: =H6*H$21 -> 0 | I28: =I6*I$21 -> 0 | J28: =J6*J$21 -> 0 | K28: =K6*K$21 -> 0 | L28: =L6*L$21 -> 0 | M28: =M6*M$21 -> 0
D29: =D7 -> HX | E29: =E7*$E$21 -> 0 | F29: =F7*$F$21 -> 8.75 | G29: =G7*G$21 -> 1.75 | H29: =H7*H$21 -> 0 | I29: =I7*I$21 -> 0 | J29: =J7*J$21 -> 0 | K29: =K7*K$21 -> 0 | L29: =L7*L$21 -> 0 | M29: =M7*M$21 -> 0
D30: =D8 -> JZ | E30: =E8*$E$21 -> 0 | F30: =F8*$F$21 -> 0 | G30: =G8*G$21 -> 1.75 | H30: =H8*H$21 -> 0 | I30: =I8*I$21 -> 0 | J30: =J8*J$21 -> 0 | K30: =K8*K$21 -> 0 | L30: =L8*L$21 -> 0 | M30: =M8*M$21 -> 0
D31: =D9 -> LW | E31: =E9*$E$21 -> 1.9444444 | F31: =F9*$F$21 -> 0 | G31: =G9*G$21 -> 0 | H31: =H9*H$21 -> 0 | I31: =I9*I$21 -> 0 | J31: =J9*J$21 -> 0 | K31: =K9*K$21 -> 0 | L31: =L9*L$21 -> 0 | M31: =M9*M$21 -> 0
D32: =D10 -> KY | E32: =E10*$E$21 -> 1.9444444 | F32: =F10*$F$21 -> 4.375 | G32: =G10*G$21 -> 1.75 | H32: =H10*H$21 -> 0 | I32: =I10*I$21 -> 0 | J32: =J10*J$21 -> 0 | K32: =K10*K$21 -> 0 | L32: =L10*L$21 -> 0 | M32: =M10*M$21 -> 0
D33: =D11 -> Jit Loong | E33: =E11*$E$21 -> 0 | F33: =F11*$F$21 -> 0 | G33: =G11*G$21 -> 0 | H33: =H11*H$21 -> 0 | I33: =I11*I$21 -> 0 | J33: =J11*J$21 -> 0 | K33: =K11*K$21 -> 0 | L33: =L11*L$21 -> 0 | M33: =M11*M$21 -> 0
D34: =D12 -> Matthew | E34: =E12*$E$21 -> 1.9444444 | F34: =F12*$F$21 -> 0 | G34: =G12*G$21 -> 0 | H34: =H12*H$21 -> 0 | I34: =I12*I$21 -> 0 | J34: =J12*J$21 -> 0 | K34: =K12*K$21 -> 0 | L34: =L12*L$21 -> 0 | M34: =M12*M$21 -> 0
D35: =D13 -> Hau Jin | E35: =E13*$E$21 -> 0 | F35: =F13*$F$21 -> 0 | G35: =G13*G$21 -> 0 | H35: =H13*H$21 -> 0 | I35: =I13*I$21 -> 0 | J35: =J13*J$21 -> 0 | K35: =K13*K$21 -> 0 | L35: =L13*L$21 -> 0 | M35: =M13*M$21 -> 0
... D39: =D17 -> ZL | E39: =E17*$E$21 -> 0 | F39: =F17*$F$21 -> 0 | G39: =G17*G$21 -> 0 | H39: =H17*H$21 -> 0 | I39: =I17*I$21 -> 0 | J39: =J17*J$21 -> 0 | K39: =K17*K$21 -> 0 | L39: =L17*L$21 -> 0 | M39: =M17*M$21 -> 0
D41: Sum | E41: =SUM(E24:E39) -> 17.5 | F41: =SUM(F24:F39) -> 43.75 | G41: =SUM(G24:G39) -> 17.5 | H41: =SUM(H24:H39) -> 0 | I41: =SUM(I24:I39) -> 0 | J41: =SUM(J24:J39) -> 0 | K41: =SUM(K24:K39) -> 0 | L41: =SUM(L24:L39) -> 0 | M41: =SUM(M24:M39) -> 0

Sheet Sealion (Poi)
A1: Tube price | B1: 69.36 | D1: Players | E1: 45296 | F1: 45298 | G1: 45305 | H1: 45340 | O1: Pay | P1: Total | S1: Frequency
A2: No. of ball | B2: 12 | D2: Poi | E2: 1 | F2: 1 | G2: 1 | H2: 1 | O2: =D2 -> Poi | P2: =SUM(E24:M24) -> 14.622024 | S2: =COUNT(E2:M2) -> 4
A3: Ball price | B3: =B1/B2 -> 5.78 | D3: ZT | F3: 1 | G3: 1 | O3: =D3 -> ZT | P3: =SUM(E25:M25) -> 6.9153571 | S3: =COUNT(E3:M3) -> 2
D4: YZ | F4: 1 | G4: 1 | H4: 1 | O4: =D4 -> YZ | P4: =SUM(E26:M26) -> 8.8420238 | S4: =COUNT(E4:M4) -> 3
A5: Tube Holder | B5: Poi | D5: KC | F5: 1 | G5: 1 | H5: 1 | O5: =D5 -> KC | P5: =SUM(E27:M27) -> 8.8420238 | S5: =COUNT(E5:M5) -> 3
D6: CJ | F6: 1 | G6: 1 | O6: =D6 -> CJ | P6: =SUM(E28:M28) -> 6.9153571 | S6: =COUNT(E6:M6) -> 2
A7: Balls left | B7: =B2-SUM(E20:M20) -> 0 | D7: HX | G7: 1 | H7: 2 | O7: =D7 -> HX | P7: =SUM(E29:M29) -> 7.4658333 | S7: =COUNT(E7:M7) -> 2
D8: JZ | G8: 1 | O8: =D8 -> JZ | P8: =SUM(E30:M30) -> 3.6125 | S8: =COUNT(E8:M8) -> 1
D9: LW | O9: =D9 -> LW | P9: =SUM(E31:M31) -> 0 | S9: =COUNT(E9:M9) -> 0
D10: KY | F10: 1 | G10: 1 | O10: =D10 -> KY | P10: =SUM(E32:M32) -> 6.9153571 | S10: =COUNT(E10:M10) -> 2
D11: Jit Loong | O11: =D11 -> Jit Loong | P11: =SUM(E33:M33) -> 0 | S11: =COUNT(E11:M11) -> 0
D12: Matthew | O12: =D12 -> Matthew | P12: =SUM(E34:M34) -> 0 | S12: =COUNT(E12:M12) -> 0
D13: Hau Jin | H13: 1 | O13: =D13 -> Hau Jin | P13: =SUM(E35:M35) -> 1.9266667 | S13: =COUNT(E13:M13) -> 1
D14: Kit Liang | O14: =D14 -> Kit Liang | P14: =SUM(E36:M36) -> 0 | S14: =COUNT(E14:M14) -> 0
D15: YL | F15: 1 | O15: =D15 -> YL | P15: =SUM(E37:M37) -> 3.3028571 | S15: =COUNT(E15:M15) -> 1
D16: YX | O16: =D16 -> YX | P16: =SUM(E38:M38) -> 0 | S16: =COUNT(E16:M16) -> 0
D17: ZL | O17: =D17 -> ZL | P17: =SUM(E39:M39) -> 0 | S17: =COUNT(E17:M17) -> 0
P18: =SUM(P2:P17) -> 69.36
D19: User | E19: =SUM(E2:E17) -> 1 | F19: =SUM(F2:F17) -> 7 | G19: =SUM(G2:G17) -> 8 | H19: =SUM(H2:H17) -> 6 | I19: =SUM(I2:I17) -> 0 | J19: =SUM(J2:J17) -> 0 | K19: =SUM(K2:K17) -> 0 | L19: =SUM(L2:L17) -> 0 | M19: =SUM(M2:M17) -> 0
D20: Ball usage | E20: 1 | F20: 4 | G20: 5 | H20: 2
D21: Weightage price | E21: =IF(E19=0, 0, $B$3*E20/E19) -> 5.78 | F21: =IF(F19=0, 0, $B$3*F20/F19) -> 3.3028571 | G21: =IF(G19=0, 0, $B$3*G20/G19) -> 3.6125 | H21: =IF(H19=0, 0, $B$3*H20/H19) -> 1.9266667 | I21: =IF(I19=0, 0, $B$3*I20/I19) -> 0 | J21: =IF(J19=0, 0, $B$3*J20/J19) -> 0 | K21: =IF(K19=0, 0, $B$3*K20/K19) -> 0 | L21: =IF(L19=0, 0, $B$3*L20/L19) -> 0 | M21: =IF(M19=0, 0, $B$3*M20/M19) -> 0
D23: Pay | E23: =E1 -> 45296 | F23: =F1 -> 45298 | G23: =G1 -> 45305 | H23: =H1 -> 45340 | I23: =I1 | J23: =J1 | K23: =K1 | L23: =L1 | M23: =M1
D24: =D2 -> Poi | E24: =E2*$E$21 -> 5.78 | F24: =F2*$F$21 -> 3.3028571 | G24: =G2*G$21 -> 3.6125 | H24: =H2*H$21 -> 1.9266667 | I24: =I2*I$21 -> 0 | J24: =J2*J$21 -> 0 | K24: =K2*K$21 -> 0 | L24: =L2*L$21 -> 0 | M24: =M2*M$21 -> 0
D25: =D3 -> ZT | E25: =E3*$E$21 -> 0 | F25: =F3*$F$21 -> 3.3028571 | G25: =G3*G$21 -> 3.6125 | H25: =H3*H$21 -> 0 | I25: =I3*I$21 -> 0 | J25: =J3*J$21 -> 0 | K25: =K3*K$21 -> 0 | L25: =L3*L$21 -> 0 | M25: =M3*M$21 -> 0
D26: =D4 -> YZ | E26: =E4*$E$21 -> 0 | F26: =F4*$F$21 -> 3.3028571 | G26: =G4*G$21 -> 3.6125 | H26: =H4*H$21 -> 1.9266667 | I26: =I4*I$21 -> 0 | J26: =J4*J$21 -> 0 | K26: =K4*K$21 -> 0 | L26: =L4*L$21 -> 0 | M26: =M4*M$21 -> 0
D27: =D5 -> KC | E27: =E5*$E$21 -> 0 | F27: =F5*$F$21 -> 3.3028571 | G27: =G5*G$21 -> 3.6125 | H27: =H5*H$21 -> 1.9266667 | I27: =I5*I$21 -> 0 | J27: =J5*J$21 -> 0 | K27: =K5*K$21 -> 0 | L27: =L5*L$21 -> 0 | M27: =M5*M$21 -> 0
D28: =D6 -> CJ | E28: =E6*$E$21 -> 0 | F28: =F6*$F$21 -> 3.3028571 | G28: =G6*G$21 -> 3.6125 | H28: =H6*H$21 -> 0 | I28: =I6*I$21 -> 0 | J28: =J6*J$21 -> 0 | K28: =K6*K$21 -> 0 | L28: =L6*L$21 -> 0 | M28: =M6*M$21 -> 0
D29: =D7 -> HX | E29: =E7*$E$21 -> 0 | F29: =F7*$F$21 -> 0 | G29: =G7*G$21 -> 3.6125 | H29: =H7*H$21 -> 3.8533333 | I29: =I7*I$21 -> 0 | J29: =J7*J$21 -> 0 | K29: =K7*K$21 -> 0 | L29: =L7*L$21 -> 0 | M29: =M7*M$21 -> 0
D30: =D8 -> JZ | E30: =E8*$E$21 -> 0 | F30: =F8*$F$21 -> 0 | G30: =G8*G$21 -> 3.6125 | H30: =H8*H$21 -> 0 | I30: =I8*I$21 -> 0 | J30: =J8*J$21 -> 0 | K30: =K8*K$21 -> 0 | L30: =L8*L$21 -> 0 | M30: =M8*M$21 -> 0
D31: =D9 -> LW | E31: =E9*$E$21 -> 0 | F31: =F9*$F$21 -> 0 | G31: =G9*G$21 -> 0 | H31: =H9*H$21 -> 0 | I31: =I9*I$21 -> 0 | J31: =J9*J$21 -> 0 | K31: =K9*K$21 -> 0 | L31: =L9*L$21 -> 0 | M31: =M9*M$21 -> 0
D32: =D10 -> KY | E32: =E10*$E$21 -> 0 | F32: =F10*$F$21 -> 3.3028571 | G32: =G10*G$21 -> 3.6125 | H32: =H10*H$21 -> 0 | I32: =I10*I$21 -> 0 | J32: =J10*J$21 -> 0 | K32: =K10*K$21 -> 0 | L32: =L10*L$21 -> 0 | M32: =M10*M$21 -> 0
D33: =D11 -> Jit Loong | E33: =E11*$E$21 -> 0 | F33: =F11*$F$21 -> 0 | G33: =G11*G$21 -> 0 | H33: =H11*H$21 -> 0 | I33: =I11*I$21 -> 0 | J33: =J11*J$21 -> 0 | K33: =K11*K$21 -> 0 | L33: =L11*L$21 -> 0 | M33: =M11*M$21 -> 0
D34: =D12 -> Matthew | E34: =E12*$E$21 -> 0 | F34: =F12*$F$21 -> 0 | G34: =G12*G$21 -> 0 | H34: =H12*H$21 -> 0 | I34: =I12*I$21 -> 0 | J34: =J12*J$21 -> 0 | K34: =K12*K$21 -> 0 | L34: =L12*L$21 -> 0 | M34: =M12*M$21 -> 0
D35: =D13 -> Hau Jin | E35: =E13*$E$21 -> 0 | F35: =F13*$F$21 -> 0 | G35: =G13*G$21 -> 0 | H35: =H13*H$21 -> 1.9266667 | I35: =I13*I$21 -> 0 | J35: =J13*J$21 -> 0 | K35: =K13*K$21 -> 0 | L35: =L13*L$21 -> 0 | M35: =M13*M$21 -> 0
... D39: =D17 -> ZL | E39: =E17*$E$21 -> 0 | F39: =F17*$F$21 -> 0 | G39: =G17*G$21 -> 0 | H39: =H17*H$21 -> 0 | I39: =I17*I$21 -> 0 | J39: =J17*J$21 -> 0 | K39: =K17*K$21 -> 0 | L39: =L17*L$21 -> 0 | M39: =M17*M$21 -> 0
D41: Sum | E41: =SUM(E24:E39) -> 5.78 | F41: =SUM(F24:F39) -> 23.12 | G41: =SUM(G24:G39) -> 28.9 | H41: =SUM(H24:H39) -> 11.56 | I41: =SUM(I24:I39) -> 0 | J41: =SUM(J24:J39) -> 0 | K41: =SUM(K24:K39) -> 0 | L41: =SUM(L24:L39) -> 0 | M41: =SUM(M24:M39) -> 0

Sheet RSL C (Poi)
A1: Tube price | B1: 76.67 | D1: Players | E1: 45236 | F1: 45242 | G1: 45250 | H1: 45257 | O1: Pay | P1: Total | S1: Frequency
A2: No. of ball | B2: 12 | D2: Poi | E2: 1 | F2: 1 | G2: 1 | H2: 1 | O2: =D2 -> Poi | P2: =SUM(E24:M24) -> 9.5431839 | S2: =COUNT(E2:M2) -> 4
A3: Ball price | B3: =B1/B2 -> 6.3891667 | D3: ZT | E3: 1 | F3: 1 | G3: 1 | H3: 1 | O3: =D3 -> ZT | P3: =SUM(E25:M25) -> 9.5431839 | S3: =COUNT(E3:M3) -> 4
D4: YZ | E4: 1 | G4: 1 | H4: 1 | O4: =D4 -> YZ | P4: =SUM(E26:M26) -> 6.3486005 | S4: =COUNT(E4:M4) -> 3
A5: Tube Holder | B5: Poi | D5: KC | E5: 1 | F5: 1 | G5: 1 | H5: 1 | O5: =D5 -> KC | P5: =SUM(E27:M27) -> 9.5431839 | S5: =COUNT(E5:M5) -> 4
D6: CJ | E6: 1 | F6: 1 | G6: 1 | H6: 1 | O6: =D6 -> CJ | P6: =SUM(E28:M28) -> 9.5431839 | S6: =COUNT(E6:M6) -> 4
A7: Balls left | B7: =B2-SUM(E20:M20) -> 0 | D7: HX | E7: 1 | F7: 1 | O7: =D7 -> HX | P7: =SUM(E29:M29) -> 4.4724167 | S7: =COUNT(E7:M7) -> 2
D8: JZ | E8: 1 | O8: =D8 -> JZ | P8: =SUM(E30:M30) -> 1.2778333 | S8: =COUNT(E8:M8) -> 1
D9: LW | F9: 1 | G9: 1 | O9: =D9 -> LW | P9: =SUM(E31:M31) -> 4.6143981 | S9: =COUNT(E9:M9) -> 2
D10: KY | E10: 1 | F10: 1 | G10: 1 | H10: 1 | O10: =D10 -> KY | P10: =SUM(E32:M32) -> 9.5431839 | S10: =COUNT(E10:M10) -> 4
D11: Jit Loong | O11: =D11 -> Jit Loong | P11: =SUM(E33:M33) -> 0 | S11: =COUNT(E11:M11) -> 0
D12: Matthew | E12: 1 | G12: 1 | H12: 1 | O12: =D12 -> Matthew | P12: =SUM(E34:M34) -> 6.3486005 | S12: =COUNT(E12:M12) -> 3
D13: Hau Jin | O13: =D13 -> Hau Jin | P13: =SUM(E35:M35) -> 0 | S13: =COUNT(E13:M13) -> 0
D14: Kit Liang | O14: =D14 -> Kit Liang | P14: =SUM(E36:M36) -> 0 | S14: =COUNT(E14:M14) -> 0
D15: YL | E15: 1 | F15: 1 | G15: 1 | O15: =D15 -> YL | P15: =SUM(E37:M37) -> 5.8922315 | S15: =COUNT(E15:M15) -> 3
D16: YX | O16: =D16 -> YX | P16: =SUM(E38:M38) -> 0 | S16: =COUNT(E16:M16) -> 0
D17: ZL | O17: =D17 -> ZL | P17: =SUM(E39:M39) -> 0 | S17: =COUNT(E17:M17) -> 0
P18: =SUM(P2:P17) -> 76.67
D19: User | E19: =SUM(E2:E17) -> 10 | F19: =SUM(F2:F17) -> 8 | G19: =SUM(G2:G17) -> 9 | H19: =SUM(H2:H17) -> 7 | I19: =SUM(I2:I17) -> 0 | J19: =SUM(J2:J17) -> 0 | K19: =SUM(K2:K17) -> 0 | L19: =SUM(L2:L17) -> 0 | M19: =SUM(M2:M17) -> 0
D20: Ball usage | E20: 2 | F20: 4 | G20: 2 | H20: 4
D21: Weightage price | E21: =IF(E19=0, 0, $B$3*E20/E19) -> 1.2778333 | F21: =IF(F19=0, 0, $B$3*F20/F19) -> 3.1945833 | G21: =IF(G19=0, 0, $B$3*G20/G19) -> 1.4198148 | H21: =IF(H19=0, 0, $B$3*H20/H19) -> 3.6509524 | I21: =IF(I19=0, 0, $B$3*I20/I19) -> 0 | J21: =IF(J19=0, 0, $B$3*J20/J19) -> 0 | K21: =IF(K19=0, 0, $B$3*K20/K19) -> 0 | L21: =IF(L19=0, 0, $B$3*L20/L19) -> 0 | M21: =IF(M19=0, 0, $B$3*M20/M19) -> 0
D23: Pay | E23: =E1 -> 45236 | F23: =F1 -> 45242 | G23: =G1 -> 45250 | H23: =H1 -> 45257 | I23: =I1 | J23: =J1 | K23: =K1 | L23: =L1 | M23: =M1
D24: =D2 -> Poi | E24: =E2*$E$21 -> 1.2778333 | F24: =F2*$F$21 -> 3.1945833 | G24: =G2*G$21 -> 1.4198148 | H24: =H2*H$21 -> 3.6509524 | I24: =I2*I$21 -> 0 | J24: =J2*J$21 -> 0 | K24: =K2*K$21 -> 0 | L24: =L2*L$21 -> 0 | M24: =M2*M$21 -> 0
D25: =D3 -> ZT | E25: =E3*$E$21 -> 1.2778333 | F25: =F3*$F$21 -> 3.1945833 | G25: =G3*G$21 -> 1.4198148 | H25: =H3*H$21 -> 3.6509524 | I25: =I3*I$21 -> 0 | J25: =J3*J$21 -> 0 | K25: =K3*K$21 -> 0 | L25: =L3*L$21 -> 0 | M25: =M3*M$21 -> 0
D26: =D4 -> YZ | E26: =E4*$E$21 -> 1.2778333 | F26: =F4*$F$21 -> 0 | G26: =G4*G$21 -> 1.4198148 | H26: =H4*H$21 -> 3.6509524 | I26: =I4*I$21 -> 0 | J26: =J4*J$21 -> 0 | K26: =K4*K$21 -> 0 | L26: =L4*L$21 -> 0 | M26: =M4*M$21 -> 0
D27: =D5 -> KC | E27: =E5*$E$21 -> 1.2778333 | F27: =F5*$F$21 -> 3.1945833 | G27: =G5*G$21 -> 1.4198148 | H27: =H5*H$21 -> 3.6509524 | I27: =I5*I$21 -> 0 | J27: =J5*J$21 -> 0 | K27: =K5*K$21 -> 0 | L27: =L5*L$21 -> 0 | M27: =M5*M$21 -> 0
D28: =D6 -> CJ | E28: =E6*$E$21 -> 1.2778333 | F28: =F6*$F$21 -> 3.1945833 | G28: =G6*G$21 -> 1.4198148 | H28: =H6*H$21 -> 3.6509524 | I28: =I6*I$21 -> 0 | J28: =J6*J$21 -> 0 | K28: =K6*K$21 -> 0 | L28: =L6*L$21 -> 0 | M28: =M6*M$21 -> 0
